<?xml version="1.0" ?>
<!-- =================================================================================== -->
<!-- |    This document was autogenerated by xacro from andresito.xacro                | -->
<!-- |    EDITING THIS FILE BY HAND IS NOT RECOMMENDED                                 | -->
<!-- =================================================================================== -->
<robot name="andresito">
  <!-- <preserveFixedJoint>true</preserveFixedJoint> -->
  <!-- CAMERA -->
  <!-- <xacro:property name="camera_link" value="realsense_link" />
    <xacro:property name="camera_relative_to" value="puller_base" />
    <xacro:property name="camera_x" value="-${puller_depth/2-0.03}" />
    <xacro:property name="camera_y" value="0.0" />
    <xacro:property name="camera_z" value="0.24" />
    <xacro:property name="camera_rotation_z" value="${180*deg_to_rad}" /> -->
  <!-- PROPERTIES -->
  <material name="blue">
    <color rgba="0 0 0.9 1"/>
  </material>
  <material name="black">
    <color rgba="0 0 0 1"/>
  </material>
  <material name="white">
    <color rgba="1 1 1 1"/>
  </material>
  <!-- <xacro:include filename="leg.xacro" />
  <xacro:include filename="leg_support.xacro" />
  <xacro:include filename="gazebo.xacro" /> -->
  <!-- LINKS -->
  <link name="base_footprint"/>
  <link name="base_link">
    <visual>
      <geometry>
        <box size="0.42 0.32 0.08"/>
      </geometry>
      <material name="blue"/>
    </visual>
    <collision>
      <geometry>
        <box size="0.42 0.32 0.08"/>
      </geometry>
    </collision>
  </link>
  <!-- <link name="center_rotation"></link> -->
  <link name="laser">
    <visual>
      <geometry>
        <cylinder length="0.12" radius="0.05"/>
      </geometry>
      <origin rpy="0 0 0" xyz="0 0 0"/>
      <material name="black"/>
    </visual>
  </link>
  <link name="left_front_wheel">
    <visual>
      <geometry>
        <cylinder length="0.06" radius="0.05"/>
        <!-- <sphere radius="${wheel_radius}"/> -->
      </geometry>
      <origin rpy="1.5707963267948966 0 0" xyz="0 0 0"/>
      <material name="black"/>
    </visual>
    <collision>
      <origin rpy="1.5707963267948966 0 0" xyz="0 0 0"/>
      <geometry>
        <cylinder length="0.06" radius="0.05"/>
        <!-- <sphere radius="${wheel_radius}"/> -->
      </geometry>
    </collision>
  </link>
  <link name="left_back_wheel">
    <visual>
      <geometry>
        <cylinder length="0.06" radius="0.05"/>
        <!-- <sphere radius="${wheel_radius}"/> -->
      </geometry>
      <origin rpy="1.5707963267948966 0 0" xyz="0 0 0"/>
      <material name="black"/>
    </visual>
    <collision>
      <origin rpy="1.5707963267948966 0 0" xyz="0 0 0"/>
      <geometry>
        <cylinder length="0.06" radius="0.05"/>
        <!-- <sphere radius="${wheel_radius}"/> -->
      </geometry>
    </collision>
  </link>
  <link name="right_front_wheel">
    <visual>
      <geometry>
        <cylinder length="0.06" radius="0.05"/>
        <!-- <sphere radius="${wheel_radius}"/> -->
      </geometry>
      <origin rpy="1.5707963267948966 0 0" xyz="0 0 0"/>
      <material name="black"/>
    </visual>
    <collision>
      <origin rpy="1.5707963267948966 0 0" xyz="0 0 0"/>
      <geometry>
        <cylinder length="0.06" radius="0.05"/>
        <!-- <sphere radius="${wheel_radius}"/> -->
      </geometry>
    </collision>
  </link>
  <link name="right_back_wheel">
    <visual>
      <geometry>
        <cylinder length="0.06" radius="0.05"/>
        <!-- <sphere radius="${wheel_radius}"/> -->
      </geometry>
      <origin rpy="1.5707963267948966 0 0" xyz="0 0 0"/>
      <material name="black"/>
    </visual>
    <collision>
      <origin rpy="1.5707963267948966 0 0" xyz="0 0 0"/>
      <geometry>
        <cylinder length="0.06" radius="0.05"/>
        <!-- <sphere radius="${wheel_radius}"/> -->
      </geometry>
    </collision>
  </link>
  <!-- JOINTS -->
  <joint name="base_joint" type="fixed">
    <origin xyz="0 -0.21 0.0"/>
    <parent link="base_footprint"/>
    <child link="base_link"/>
  </joint>
  <joint name="base_link_left_front_wheel" type="continuous">
    <parent link="base_link"/>
    <child link="left_front_wheel"/>
    <origin xyz="0.16 0.21 0.0"/>
    <axis xyz="0 1 0"/>
  </joint>
  <joint name="base_link_left_back_wheel" type="continuous">
    <parent link="base_link"/>
    <child link="left_back_wheel"/>
    <origin xyz="0.16 -0.21 0.0"/>
    <axis xyz="0 1 0"/>
  </joint>
  <joint name="base_link_right_front_wheel" type="continuous">
    <parent link="base_link"/>
    <child link="right_front_wheel"/>
    <origin xyz="-0.16 0.21 0.0"/>
    <axis xyz="0 1 0"/>
  </joint>
  <joint name="base_link_right_back_wheel" type="continuous">
    <parent link="base_link"/>
    <child link="right_back_wheel"/>
    <origin xyz="-0.16 -0.21 0.0"/>
    <axis xyz="0 1 0"/>
  </joint>
  <joint name="base_link_laser" type="fixed">
    <parent link="base_link"/>
    <child link="laser"/>
    <origin xyz="0 0 0.08"/>
    <axis xyz="0 0 1"/>
  </joint>

  <!--**************************************************************-->
  <!-- IMU -->
  <!--**************************************************************-->
  <link name="imu_link">
    <!--INERTIA-->
    <!--Not calling macro, just small values-->
    <inertial>
      <mass value="0.005"/>
      <inertia ixx="0.001" ixy="0.0" ixz="0.0" iyy="0.001" iyz="0.0" izz="0.001"/>
    </inertial>
    <collision>
      <geometry>
        <box size="0.0 0.0 0.0"/>
      </geometry>
    </collision>
    <visual>
      <geometry>
        <box size="0.0 0.0 0.0"/>
      </geometry>
      <material name="dark"/>
    </visual>
  </link>

  <joint name="imu_joint" type="fixed">
    <!-- <origin rpy="3.1415922 0 3.1415922" xyz="-0.646 0.0 -0.055"/> -->
    <origin xyz="0.03 0 0.08"/>
    <axis xyz="0 0 1"/>
    <child link="imu_link"/>
    <parent link="base_link"/>
  </joint>

  <odometry_frame>odom</odometry_frame>
</robot>
