<sdf version='1.7'>
  <model name='me00'>
    <link name='base_footprint'>
      <inertial>
        <pose>1.7e-05 0 0.218942 0 -0 0</pose>
        <mass>200.625</mass>
        <inertia>
          <ixx>15.1315</ixx>
          <ixy>0.025786</ixy>
          <ixz>-0.000525203</ixz>
          <iyy>35.0599</iyy>
          <iyz>-8.47033e-22</iyz>
          <izz>45.9157</izz>
        </inertia>
      </inertial>
      <collision name='base_footprint_fixed_joint_lump__base_link_collision'>
        <pose>0 0 0.219 0 -0 0</pose>
        <geometry>
          <mesh>
            <scale>0.001 0.001 0.001</scale>
            <uri>model://me00_description/mesh/base.stl</uri>
          </mesh>
        </geometry>
        <surface>
          <contact>
            <ode/>
          </contact>
          <friction>
            <ode/>
          </friction>
        </surface>
      </collision>
      <collision name='base_footprint_fixed_joint_lump__laser_back_link_collision_1'>
        <pose>-0.64 -0.37 0.199 0 0 -2.3562</pose>
        <geometry>
          <mesh>
            <scale>0.001 0.001 0.001</scale>
            <uri>model://me00_description/mesh/laser.stl</uri>
          </mesh>
        </geometry>
        <surface>
          <contact>
            <ode/>
          </contact>
          <friction>
            <ode/>
          </friction>
        </surface>
      </collision>
      <collision name='base_footprint_fixed_joint_lump__camera_link_collision_2'>
        <pose>0.7 0 0.369 0 -0 0</pose>
        <geometry>
          <box>
            <size>0.1 0.05 0.05</size>
          </box>
        </geometry>
        <surface>
          <contact>
            <ode/>
          </contact>
          <friction>
            <ode/>
          </friction>
        </surface>
      </collision>
      <collision name='base_footprint_fixed_joint_lump__laser_front_link_collision_3'>
        <pose>0.64 0.37 0.199 0 -0 0.785398</pose>
        <geometry>
          <mesh>
            <scale>0.001 0.001 0.001</scale>
            <uri>model://me00_description/mesh/laser.stl</uri>
          </mesh>
        </geometry>
        <surface>
          <contact>
            <ode/>
          </contact>
          <friction>
            <ode/>
          </friction>
        </surface>
      </collision>
      <visual name='base_footprint_fixed_joint_lump__base_link_visual'>
        <pose>0 0 0.219 0 -0 0</pose>
        <geometry>
          <mesh>
            <scale>0.001 0.001 0.001</scale>
            <uri>model://me00_description/mesh/base.stl</uri>
          </mesh>
        </geometry>
        <material>
          <script>
            <name>Gazebo/FlatBlack</name>
            <uri>file://media/materials/scripts/gazebo.material</uri>
          </script>
        </material>
      </visual>
      <visual name='base_footprint_fixed_joint_lump__laser_back_link_visual_1'>
        <pose>-0.64 -0.37 0.199 0 0 -2.3562</pose>
        <geometry>
          <mesh>
            <scale>0.001 0.001 0.001</scale>
            <uri>model://me00_description/mesh/laser.stl</uri>
          </mesh>
        </geometry>
        <material>
          <script>
            <name>Gazebo/Yellow</name>
            <uri>file://media/materials/scripts/gazebo.material</uri>
          </script>
        </material>
      </visual>
      <visual name='base_footprint_fixed_joint_lump__camera_link_visual_2'>
        <pose>0.7 0 0.369 0 -0 0</pose>
        <geometry>
          <box>
            <size>0.1 0.05 0.05</size>
          </box>
        </geometry>
        <material>
          <script>
            <name>Gazebo/FlatBlack</name>
            <uri>file://media/materials/scripts/gazebo.material</uri>
          </script>
        </material>
      </visual>
      <visual name='base_footprint_fixed_joint_lump__laser_front_link_visual_3'>
        <pose>0.64 0.37 0.199 0 -0 0.785398</pose>
        <geometry>
          <mesh>
            <scale>0.001 0.001 0.001</scale>
            <uri>model://me00_description/mesh/laser.stl</uri>
          </mesh>
        </geometry>
        <material>
          <script>
            <name>Gazebo/Yellow</name>
            <uri>file://media/materials/scripts/gazebo.material</uri>
          </script>
        </material>
      </visual>
      <velocity_decay/>
      <velocity_decay/>
      <sensor name='laser_back_link' type='ray'>
        <visualize>1</visualize>
        <update_rate>12.5</update_rate>
        <ray>
          <scan>
            <horizontal>
              <samples>541</samples>
              <resolution>1</resolution>
              <min_angle>-2.35619</min_angle>
              <max_angle>2.35619</max_angle>
            </horizontal>
          </scan>
          <range>
            <min>0.05</min>
            <max>15</max>
            <resolution>0.01</resolution>
          </range>
          <noise>
            <type>gaussian</type>
            <mean>0</mean>
            <stddev>0.01</stddev>
          </noise>
        </ray>
        <plugin name='gazebo_ros_laser_back_link_controller' filename='libgazebo_ros_ray_sensor.so'>
          <ros>
            <namespace>/me00_1</namespace>
            <argument>~/out:=Laser_Back/laser_scan</argument>
          </ros>
          <frame_name>laser_back_link</frame_name>
          <output_type>sensor_msgs/LaserScan</output_type>
        </plugin>
        <pose>-0.64 -0.37 0.199 0 -0 -2.35619</pose>
      </sensor>
      <velocity_decay/>
      <sensor name='Camera' type='depth'>
        <always_on>1</always_on>
        <update_rate>15</update_rate>
        <camera name='Camera'>
          <distortion>
            <k1>0</k1>
            <k2>0</k2>
            <k3>0</k3>
            <p1>0</p1>
            <p2>0</p2>
            <center>0 0</center>
          </distortion>
          <horizontal_fov>1.047</horizontal_fov>
          <image>
            <width>320</width>
            <height>240</height>
          </image>
          <clip>
            <near>0.1</near>
            <far>100</far>
          </clip>
        </camera>
        <plugin name='plugin_name' filename='libgazebo_ros_camera.so'>
          <ros>
            <namespace>/me00_1</namespace>
            <argument>image_raw:=image_raw</argument>
          </ros>
          <camera_name>Camera</camera_name>
          <frame_name>camera_link</frame_name>
          <hack_baseline>0.07</hack_baseline>
          <min_depth>0.001</min_depth>
        </plugin>
        <pose>0.7 0 0.369 0 -0 0</pose>
      </sensor>
      <gravity>1</gravity>
      <velocity_decay/>
      <sensor name='laser_front_link' type='ray'>
        <visualize>1</visualize>
        <update_rate>12.5</update_rate>
        <ray>
          <scan>
            <horizontal>
              <samples>541</samples>
              <resolution>1</resolution>
              <min_angle>-2.35619</min_angle>
              <max_angle>2.35619</max_angle>
            </horizontal>
          </scan>
          <range>
            <min>0.05</min>
            <max>15</max>
            <resolution>0.01</resolution>
          </range>
          <noise>
            <type>gaussian</type>
            <mean>0</mean>
            <stddev>0.01</stddev>
          </noise>
        </ray>
        <plugin name='gazebo_ros_laser_front_link_controller' filename='libgazebo_ros_ray_sensor.so'>
          <ros>
            <namespace>/me00_1</namespace>
            <argument>~/out:=Laser_Front/laser_scan</argument>
          </ros>
          <frame_name>laser_front_link</frame_name>
          <output_type>sensor_msgs/LaserScan</output_type>
        </plugin>
        <pose>0.64 0.37 0.199 0 -0 0.785398</pose>
      </sensor>
    </link>
    <joint name='back_caster_rotation_joint' type='revolute'>
      <pose relative_to='base_footprint'>-0.5 0 0.129 0 -0 0</pose>
      <parent>base_footprint</parent>
      <child>back_caster_rotation_link</child>
      <axis>
        <xyz>0 0 1</xyz>
        <limit>
          <lower>-1e+16</lower>
          <upper>1e+16</upper>
        </limit>
        <dynamics>
          <damping>0.01</damping>
          <friction>0</friction>
          <spring_reference>0</spring_reference>
          <spring_stiffness>0</spring_stiffness>
        </dynamics>
      </axis>
    </joint>
    <link name='back_caster_rotation_link'>
      <pose relative_to='back_caster_rotation_joint'>0 0 0 0 -0 0</pose>
      <inertial>
        <pose>0 0 -0.0425 0 -0 1.5708</pose>
        <mass>10</mass>
        <inertia>
          <ixx>0.000584452</ixx>
          <ixy>0</ixy>
          <ixz>0</ixz>
          <iyy>0.000528726</iyy>
          <iyz>0</iyz>
          <izz>0.000179236</izz>
        </inertia>
      </inertial>
      <collision name='back_caster_rotation_link_collision'>
        <pose>0 0 0 0 -0 3.14159</pose>
        <geometry>
          <mesh>
            <scale>0.001 0.001 0.001</scale>
            <uri>model://me00_description/mesh/caster_base_test.stl</uri>
          </mesh>
        </geometry>
        <surface>
          <contact>
            <ode>
              <kp>1e+07</kp>
              <kd>1</kd>
            </ode>
          </contact>
          <friction>
            <ode>
              <mu>0.1</mu>
              <mu2>0.1</mu2>
            </ode>
          </friction>
        </surface>
      </collision>
      <visual name='back_caster_rotation_link_visual'>
        <pose>0 0 0 0 -0 3.14159</pose>
        <geometry>
          <mesh>
            <scale>0.001 0.001 0.001</scale>
            <uri>model://me00_description/mesh/caster_base_test.stl</uri>
          </mesh>
        </geometry>
        <material>
          <script>
            <name>Gazebo/Gray</name>
            <uri>file://media/materials/scripts/gazebo.material</uri>
          </script>
        </material>
      </visual>
      <gravity>1</gravity>
      <velocity_decay/>
    </link>
    <joint name='back_caster_wheel_joint' type='revolute'>
      <pose relative_to='back_caster_rotation_link'>-0.038 0 -0.079 0 -0 0</pose>
      <parent>back_caster_rotation_link</parent>
      <child>back_caster_wheel_link</child>
      <axis>
        <xyz>0 1 0</xyz>
        <limit>
          <lower>-1e+16</lower>
          <upper>1e+16</upper>
        </limit>
        <dynamics>
          <spring_reference>0</spring_reference>
          <spring_stiffness>0</spring_stiffness>
        </dynamics>
      </axis>
    </joint>
    <link name='back_caster_wheel_link'>
      <pose relative_to='back_caster_wheel_joint'>0 0 0 0 -0 0</pose>
      <inertial>
        <pose>0 0 0 1.5708 -0 0</pose>
        <mass>5</mass>
        <inertia>
          <ixx>0.00316667</ixx>
          <ixy>0</ixy>
          <ixz>0</ixz>
          <iyy>0.00316667</iyy>
          <iyz>0</iyz>
          <izz>0.00625</izz>
        </inertia>
      </inertial>
      <collision name='back_caster_wheel_link_collision'>
        <pose>0 0 0 0 -0 3.14159</pose>
        <geometry>
          <mesh>
            <scale>0.001 0.001 0.001</scale>
            <uri>model://me00_description/mesh/caster_wheel.stl</uri>
          </mesh>
        </geometry>
        <surface>
          <contact>
            <ode>
              <kp>1e+07</kp>
              <kd>1</kd>
            </ode>
          </contact>
          <friction>
            <ode>
              <mu>0.1</mu>
              <mu2>0.1</mu2>
            </ode>
          </friction>
        </surface>
      </collision>
      <visual name='back_caster_wheel_link_visual'>
        <pose>0 0 0 0 -0 3.14159</pose>
        <geometry>
          <mesh>
            <scale>0.001 0.001 0.001</scale>
            <uri>model://me00_description/mesh/caster_wheel.stl</uri>
          </mesh>
        </geometry>
        <material>
          <script>
            <name>Gazebo/Blue</name>
            <uri>file://media/materials/scripts/gazebo.material</uri>
          </script>
        </material>
      </visual>
      <gravity>1</gravity>
      <velocity_decay/>
    </link>
    <joint name='front_caster_rotation_joint' type='revolute'>
      <pose relative_to='base_footprint'>0.5 0 0.129 0 -0 0</pose>
      <parent>base_footprint</parent>
      <child>front_caster_rotation_link</child>
      <axis>
        <xyz>0 0 1</xyz>
        <limit>
          <lower>-1e+16</lower>
          <upper>1e+16</upper>
        </limit>
        <dynamics>
          <damping>0.01</damping>
          <friction>0</friction>
          <spring_reference>0</spring_reference>
          <spring_stiffness>0</spring_stiffness>
        </dynamics>
      </axis>
    </joint>
    <link name='front_caster_rotation_link'>
      <pose relative_to='front_caster_rotation_joint'>0 0 0 0 -0 0</pose>
      <inertial>
        <pose>0 0 -0.0425 0 -0 1.5708</pose>
        <mass>10</mass>
        <inertia>
          <ixx>0.000584452</ixx>
          <ixy>0</ixy>
          <ixz>0</ixz>
          <iyy>0.000528726</iyy>
          <iyz>0</iyz>
          <izz>0.000179236</izz>
        </inertia>
      </inertial>
      <collision name='front_caster_rotation_link_collision'>
        <pose>0 0 0 0 -0 3.14159</pose>
        <geometry>
          <mesh>
            <scale>0.001 0.001 0.001</scale>
            <uri>model://me00_description/mesh/caster_base_test.stl</uri>
          </mesh>
        </geometry>
        <surface>
          <contact>
            <ode>
              <kp>1e+07</kp>
              <kd>1</kd>
            </ode>
          </contact>
          <friction>
            <ode>
              <mu>0.1</mu>
              <mu2>0.1</mu2>
            </ode>
          </friction>
        </surface>
      </collision>
      <visual name='front_caster_rotation_link_visual'>
        <pose>0 0 0 0 -0 3.14159</pose>
        <geometry>
          <mesh>
            <scale>0.001 0.001 0.001</scale>
            <uri>model://me00_description/mesh/caster_base_test.stl</uri>
          </mesh>
        </geometry>
        <material>
          <script>
            <name>Gazebo/Gray</name>
            <uri>file://media/materials/scripts/gazebo.material</uri>
          </script>
        </material>
      </visual>
      <gravity>1</gravity>
      <velocity_decay/>
    </link>
    <joint name='front_caster_wheel_joint' type='revolute'>
      <pose relative_to='front_caster_rotation_link'>-0.038 0 -0.079 0 -0 0</pose>
      <parent>front_caster_rotation_link</parent>
      <child>front_caster_wheel_link</child>
      <axis>
        <xyz>0 1 0</xyz>
        <limit>
          <lower>-1e+16</lower>
          <upper>1e+16</upper>
        </limit>
        <dynamics>
          <spring_reference>0</spring_reference>
          <spring_stiffness>0</spring_stiffness>
        </dynamics>
      </axis>
    </joint>
    <link name='front_caster_wheel_link'>
      <pose relative_to='front_caster_wheel_joint'>0 0 0 0 -0 0</pose>
      <inertial>
        <pose>0 0 0 1.5708 -0 0</pose>
        <mass>5</mass>
        <inertia>
          <ixx>0.00316667</ixx>
          <ixy>0</ixy>
          <ixz>0</ixz>
          <iyy>0.00316667</iyy>
          <iyz>0</iyz>
          <izz>0.00625</izz>
        </inertia>
      </inertial>
      <collision name='front_caster_wheel_link_collision'>
        <pose>0 0 0 0 -0 3.14159</pose>
        <geometry>
          <mesh>
            <scale>0.001 0.001 0.001</scale>
            <uri>model://me00_description/mesh/caster_wheel.stl</uri>
          </mesh>
        </geometry>
        <surface>
          <contact>
            <ode>
              <kp>1e+07</kp>
              <kd>1</kd>
            </ode>
          </contact>
          <friction>
            <ode>
              <mu>0.1</mu>
              <mu2>0.1</mu2>
            </ode>
          </friction>
        </surface>
      </collision>
      <visual name='front_caster_wheel_link_visual'>
        <pose>0 0 0 0 -0 3.14159</pose>
        <geometry>
          <mesh>
            <scale>0.001 0.001 0.001</scale>
            <uri>model://me00_description/mesh/caster_wheel.stl</uri>
          </mesh>
        </geometry>
        <material>
          <script>
            <name>Gazebo/Blue</name>
            <uri>file://media/materials/scripts/gazebo.material</uri>
          </script>
        </material>
      </visual>
      <gravity>1</gravity>
      <velocity_decay/>
    </link>
    <joint name='wheel_left_joint' type='revolute'>
      <pose relative_to='base_footprint'>0 0.3 0.1 0 -0 0</pose>
      <parent>base_footprint</parent>
      <child>wheel_left_link</child>
      <axis>
        <xyz>0 1 0</xyz>
        <limit>
          <lower>-1e+16</lower>
          <upper>1e+16</upper>
        </limit>
        <dynamics>
          <spring_reference>0</spring_reference>
          <spring_stiffness>0</spring_stiffness>
        </dynamics>
      </axis>
    </joint>
    <link name='wheel_left_link'>
      <pose relative_to='wheel_left_joint'>0 0 0 0 -0 0</pose>
      <inertial>
        <pose>0 0 0 1.5708 -0 0</pose>
        <mass>40</mass>
        <inertia>
          <ixx>0.105333</ixx>
          <ixy>0</ixy>
          <ixz>0</ixz>
          <iyy>0.105333</iyy>
          <iyz>0</iyz>
          <izz>0.2</izz>
        </inertia>
      </inertial>
      <collision name='wheel_left_link_collision'>
        <pose>0 0 0 0 -0 0</pose>
        <geometry>
          <mesh>
            <scale>0.001 0.001 0.001</scale>
            <uri>model://me00_description/mesh/wheel.stl</uri>
          </mesh>
        </geometry>
        <surface>
          <contact>
            <ode>
              <kp>1e+07</kp>
              <kd>1</kd>
              <min_depth>0.01</min_depth>
            </ode>
          </contact>
          <friction>
            <ode>
              <mu>0.9</mu>
              <mu2>0.9</mu2>
            </ode>
          </friction>
        </surface>
      </collision>
      <visual name='wheel_left_link_visual'>
        <pose>0 0 0 0 -0 0</pose>
        <geometry>
          <mesh>
            <scale>0.001 0.001 0.001</scale>
            <uri>model://me00_description/mesh/wheel.stl</uri>
          </mesh>
        </geometry>
        <material>
          <script>
            <name>Gazebo/FlatBlack</name>
            <uri>file://media/materials/scripts/gazebo.material</uri>
          </script>
        </material>
      </visual>
      <gravity>1</gravity>
      <velocity_decay/>
    </link>
    <joint name='wheel_right_joint' type='revolute'>
      <pose relative_to='base_footprint'>0 -0.3 0.1 0 -0 0</pose>
      <parent>base_footprint</parent>
      <child>wheel_right_link</child>
      <axis>
        <xyz>0 1 0</xyz>
        <limit>
          <lower>-1e+16</lower>
          <upper>1e+16</upper>
        </limit>
        <dynamics>
          <spring_reference>0</spring_reference>
          <spring_stiffness>0</spring_stiffness>
        </dynamics>
      </axis>
    </joint>
    <link name='wheel_right_link'>
      <pose relative_to='wheel_right_joint'>0 0 0 0 -0 0</pose>
      <inertial>
        <pose>0 0 0 1.5708 -0 0</pose>
        <mass>40</mass>
        <inertia>
          <ixx>0.105333</ixx>
          <ixy>0</ixy>
          <ixz>0</ixz>
          <iyy>0.105333</iyy>
          <iyz>0</iyz>
          <izz>0.2</izz>
        </inertia>
      </inertial>
      <collision name='wheel_right_link_collision'>
        <pose>0 0 0 0 -0 0</pose>
        <geometry>
          <mesh>
            <scale>0.001 0.001 0.001</scale>
            <uri>model://me00_description/mesh/wheel.stl</uri>
          </mesh>
        </geometry>
        <surface>
          <contact>
            <ode>
              <kp>1e+07</kp>
              <kd>1</kd>
              <min_depth>0.01</min_depth>
            </ode>
          </contact>
          <friction>
            <ode>
              <mu>0.9</mu>
              <mu2>0.9</mu2>
            </ode>
          </friction>
        </surface>
      </collision>
      <visual name='wheel_right_link_visual'>
        <pose>0 0 0 0 -0 0</pose>
        <geometry>
          <mesh>
            <scale>0.001 0.001 0.001</scale>
            <uri>model://me00_description/mesh/wheel.stl</uri>
          </mesh>
        </geometry>
        <material>
          <script>
            <name>Gazebo/FlatBlack</name>
            <uri>file://media/materials/scripts/gazebo.material</uri>
          </script>
        </material>
      </visual>
      <gravity>1</gravity>
      <velocity_decay/>
    </link>
    <static>0</static>
    <plugin name='plugin_joint_state' filename='libgazebo_ros_joint_state_publisher.so'>
      <ros>
        <namespace>/me00_1</namespace>
        <argument>joint_states:=Description/joint_states</argument>
      </ros>
      <update_rate>15.0</update_rate>
      <joint_name>wheel_left_joint</joint_name>
      <joint_name>wheel_right_joint</joint_name>
      <joint_name>front_caster_wheel_joint</joint_name>
      <joint_name>back_caster_wheel_joint</joint_name>
      <joint_name>front_caster_rotation_joint</joint_name>
      <joint_name>back_caster_rotation_joint</joint_name>
    </plugin>
    <plugin name='plugin_diff_drive' filename='libgazebo_ros_diff_drive.so'>
      <ros>
        <namespace>/me00_1</namespace>
        <argument>cmd_vel:=Control/cmd_vel</argument>
        <argument>odom:=Wheelmotor/odom</argument>
        <argument>/tf:=tf</argument>
        <argument>/tf_static:=tf_static</argument>
      </ros>
      <update_rate>15.0</update_rate>
      <left_joint>wheel_left_joint</left_joint>
      <right_joint>wheel_right_joint</right_joint>
      <wheel_separation>0.6</wheel_separation>
      <wheel_diameter>0.2</wheel_diameter>
      <max_wheel_torque>30.0</max_wheel_torque>
      <max_wheel_acceleration>0.0</max_wheel_acceleration>
      <command_topic>cmd_vel</command_topic>
      <publish_odom>1</publish_odom>
      <publish_odom_tf>1</publish_odom_tf>
      <publish_wheel_tf>1</publish_wheel_tf>
      <odometry_topic>odom</odometry_topic>
      <odometry_frame>odom</odometry_frame>
      <robot_base_frame>base_footprint</robot_base_frame>
    </plugin>
  </model>
</sdf>
